Workbook

Sheet aux
C2: Pedidos Zé Delivery | D2: Pedidos mídia | E2: % mês | F2: YTD
B3: 45292 | C3: 4912117 | D3: 225803 | E3: =D3/C3 -> 0.045968571 | F3: =D3/C3 -> 0.045968571
B4: 45323 | C4: 5277099 | D4: 1641396 | E4: =D4/C4 -> 0.31104135 | F4: =SUM(D3:D4)/SUM(C3:C4) -> 0.18325247
B5: 45352 | C5: 5995629 | D5: 1411000 | E5: =D5/C5 -> 0.23533811 | F5: =SUM(D3:D5)/SUM(C3:C5) -> 0.20254744
B6: 45383 | E6: =D6/C6 -> #DIV/0! | F6: =SUM(D3:D6)/SUM(C3:C6) -> 0.20254744
B7: 45413 | E7: =D7/C7 -> #DIV/0! | F7: =SUM(D3:D7)/SUM(C3:C7) -> 0.20254744
B8: 45444 | E8: =D8/C8 -> #DIV/0! | F8: =SUM(D3:D8)/SUM(C3:C8) -> 0.20254744
B9: 45474 | E9: =D9/C9 -> #DIV/0! | F9: =SUM(D3:D9)/SUM(C3:C9) -> 0.20254744
B10: 45505 | E10: =D10/C10 -> #DIV/0! | F10: =SUM(D3:D10)/SUM(C3:C10) -> 0.20254744
B11: 45536 | E11: =D11/C11 -> #DIV/0! | F11: =SUM(D3:D11)/SUM(C3:C11) -> 0.20254744
B12: 45566 | E12: =D12/C12 -> #DIV/0! | F12: =SUM(D2:D12)/SUM(C2:C12) -> 0.20254744
B13: 45597 | E13: =D13/C13 -> #DIV/0! | F13: =SUM(D3:D13)/SUM(C3:C13) -> 0.20254744
B14: 45627 | E14: =D14/C14 -> #DIV/0! | F14: =SUM(D3:D14)/SUM(C3:C14) -> 0.20254744
D17: Considerar linha que fala de BF
C18: Pedidos Zé Delivery | D18: Pedidos mídia | E18: % mês | F18: YTD
B19: 45292 | C19: 4912117 | D19: =79222+19500 -> 98722 | E19: 0.0297 | F19: =D19/C19 -> 0.020097648
B20: 45323 | C20: 5277099 | D20: =47058+347639 -> 394697 | E20: 0.1551 | F20: =SUM(D19:D20)/SUM(C19:C20) -> 0.04842561
B21: 45352 | C21: 5995629 | D21: =32482+315166 -> 347648 | E21: 0.1058 | F21: =SUM(D19:D21)/SUM(C19:C21) -> 0.05196633
B22: 45383 | C22: 5217685 | D22: =19998+297754 -> 317752 | E22: =D22/C22 -> 0.060899039 | F22: =SUM(D19:D22)/SUM(C19:C22) -> 0.054144019
B23: 45413 | E23: =D23/C23 -> #DIV/0! | F23: =SUM(D19:D23)/SUM(C19:C23) -> 0.054144019
B24: 45444 | E24: =D24/C24 -> #DIV/0! | F24: =SUM(D19:D24)/SUM(C19:C24) -> 0.054144019
B25: 45474 | E25: =D25/C25 -> #DIV/0! | F25: =SUM(D19:D25)/SUM(C19:C25) -> 0.054144019
B26: 45505 | E26: =D26/C26 -> #DIV/0! | F26: =SUM(D19:D26)/SUM(C19:C26) -> 0.054144019
B27: 45536 | E27: =D27/C27 -> #DIV/0! | F27: =SUM(D19:D27)/SUM(C19:C27) -> 0.054144019
B28: 45566 | E28: =D28/C28 -> #DIV/0! | F28: =SUM(D18:D28)/SUM(C18:C28) -> 0.054144019
B29: 45597 | E29: =D29/C29 -> #DIV/0! | F29: =SUM(D19:D29)/SUM(C19:C29) -> 0.054144019
B30: 45627 | E30: =D30/C30 -> #DIV/0! | F30: =SUM(D19:D30)/SUM(C19:C30) -> 0.054144019
D35: Considerar linhas que falam de Bottom Funnel
D36: Acompanhamento de Resultados - Midia Perf.xlsx

Sheet MANAGERIAL DASHBOARD_2026
B2: ROI DASHBOARD - 2026
B3: PILAR | C3: KPI | D3: OWNER | E3: TARGET | F3: Brahma | G3: Budweiser | H3: Corona | I3: Spaten | J3: Stella Artois | K3: Skol | L3: TT | M3: Beats | N3: Guaraná | O3: Tônica | P3: Fusion | Q3: Mike's | R3: Flying Fish | S3: Brutal Fruit | T3: Zé Delivery | U3: TT | V3: LE FY | W3: LE FY | X3: FY'25 | Y3: FY'24 | Z3: FY'23
L4: Beer | U4: Portfolio | V4: Beer | W4: Portfolio
B5: Audience first | C5: 1st Party Impressions | D5: Monks | E5: 22% - 32% | F5: =Brahma!R4 -> 0.22202073 | G5: =Budweiser!R4 -> 0.24037612 | H5: =Corona!R4 -> 0.21410561 | I5: =Spaten!R4 -> 0.16046978 | J5: ='Stella Artois'!R4 -> 0.18640949 | K5: =Skol!R4 -> 0.27993287 | L5: =BEER!R4 -> 0.21396285 | M5: =Beats!R4 -> 0.26231191 | N5: 0.11 | O5: =Tonica!$R4 -> 0.32562304 | P5: =Fusion!$R4 -> NA | Q5: =Mikes!$R4 -> NA | R5: ='Flying Fish'!R4 -> NA | S5: ='Brutal Fruit'!R4 -> NA | T5: ='Zé Delivery'!R4 -> 0.40646508 | U5: =PORTFOLIO!R4 -> 0.23846385 | V5: NA | W5: NA | Y5: 0.28 | Z5: 0.32
B6: Digital Assept Optimization | C6: Campaigns > 12 weeks | D6: Monks | E6: 0.8 | F6: =Brahma!R5 -> 1 | G6: =Budweiser!R5 -> 0 | H6: =Corona!R5 -> 1 | I6: =Spaten!R5 -> 1 | J6: ='Stella Artois'!R5 -> 1 | K6: =Skol!R5 -> 0 | L6: =BEER!R5 -> 1 | M6: =Beats!R5 -> 0 | N6: 0.5 | O6: =Tonica!R5 -> 0 | P6: =Fusion!$R5 -> 0 | Q6: =Mikes!$R5 -> 0 | R6: ='Flying Fish'!R5 -> 0 | S6: ='Brutal Fruit'!R5 -> 0 | T6: ='Zé Delivery'!R5 -> 0 | U6: =PORTFOLIO!R5 -> 1 | V6: =BEER!S5 -> 1 | W6: =PORTFOLIO!S5 -> 1 | Y6: 0.56 | Z6: N/A
C7: % of videos less than 10s | E7: 0.8 | F7: =Brahma!R6 -> 1 | G7: =Budweiser!R6 -> 1 | H7: =Corona!R6 -> 1 | I7: =Spaten!R6 -> 0.88157875 | J7: ='Stella Artois'!R6 -> 0.96436303 | K7: =Skol!R6 -> 0.90626329 | L7: =BEER!R6 -> 0.95684969 | M7: =Beats!R6 -> 0.67525649 | N7: 0.68 | O7: =Tonica!R6 -> 0.24229177 | P7: =Fusion!$R6 -> NA | Q7: =Mikes!$R6 -> NA | R7: ='Flying Fish'!R6 -> NA | S7: ='Brutal Fruit'!R6 -> 0.40307293 | T7: ='Zé Delivery'!R6 -> NA | U7: =PORTFOLIO!R6 -> 0.90260754 | V7: NA | W7: NA | Y7: 0.77 | Z7: 0.7
C8: Weeks above minimum reach | D8: Meta | E8: 0.8 | F8: =Brahma!R7 -> 1 | G8: =Budweiser!R7 -> 1 | H8: =Corona!R7 -> 1 | I8: =Spaten!R7 -> 1 | J8: ='Stella Artois'!R7 -> 1 | K8: =Skol!R7 -> 1 | L8: =BEER!R7 -> 0 | M8: =Beats!R7 -> 1 | N8: 0.84 | O8: =Tonica!R7 -> 0.75 | P8: =Fusion!$R7 -> 0 | Q8: =Mikes!$R7 -> 0 | R8: ='Flying Fish'!R7 -> 0.5 | S8: ='Brutal Fruit'!R7 -> 0.75 | T8: ='Zé Delivery'!R7 -> 1 | U8: =PORTFOLIO!R7 -> 0 | V8: NA | W8: NA | Y8: NA | Z8: 0.84
C9: Weekly Frequency FB (>=2 e <=3) | E9: 0.8 | F9: =Brahma!R8 -> 1 | G9: =Budweiser!R8 -> 1 | H9: =Corona!R8 -> 1 | I9: =Spaten!R8 -> 0.72 | J9: ='Stella Artois'!R8 -> 1 | K9: =Skol!R8 -> 1 | L9: =BEER!R8 -> 0.86 | M9: =Beats!R8 -> 1 | N9: 0.59 | O9: =Tonica!R8 -> 0 | P9: =Fusion!$R8 -> 0 | Q9: =Mikes!$R8 -> 0 | R9: ='Flying Fish'!R8 -> 0.94 | S9: ='Brutal Fruit'!R8 -> 0 | T9: ='Zé Delivery'!R8 -> 1 | U9: =PORTFOLIO!R8 -> 0.84 | V9: NA | W9: NA | Y9: 0.55 | Z9: 0.55
C10: YouTube Weekly Reach: >=30% + 4 Weeks | D10: Google | E10: 0.3 | F10: =Brahma!R9 -> 0.277 | G10: =Budweiser!R9 -> 0.277 | H10: =Corona!R9 -> 0.266 | I10: =Spaten!R9 -> 0.213 | J10: ='Stella Artois'!R9 -> 0.117 | K10: =Skol!R9 -> 0.455 | L10: =BEER!R9 -> 0.262 | M10: =Beats!R9 -> NA | N10: 0.24 | O10: =Tonica!R9 -> 0.36 | P10: =Fusion!$R9 -> NA | Q10: =Mikes!$R9 -> NA | R10: ='Flying Fish'!R9 -> NA | S10: ='Brutal Fruit'!R9 -> NA | T10: ='Zé Delivery'!R9 -> 0.018 | U10: =PORTFOLIO!R9 -> 0.262 | V10: NA | W10: NA | Y10: 0.32 | Z10: 0.28
C11: AI Powered Video Reach Campaign + 2 Ad formats | E11: 0.45 | F11: =Brahma!R10 -> 1 | G11: =Budweiser!R10 -> 0.239 | H11: =Corona!R10 -> 0.565 | I11: =Spaten!R10 -> 0.463 | J11: ='Stella Artois'!R10 -> 0.498 | K11: =Skol!R10 -> 1 | L11: =BEER!R10 -> 0.589 | M11: =Beats!R10 -> NA | N11: 0.43 | O11: =Tonica!R10 -> 0.65 | P11: =Fusion!$R10 -> NA | Q11: =Mikes!$R10 -> NA | R11: ='Flying Fish'!R10 -> NA | S11: ='Brutal Fruit'!R10 -> NA | T11: ='Zé Delivery'!R10 -> NA | U11: =PORTFOLIO!R10 -> 0.589 | V11: NA | W11: NA | Y11: NA | Z11: NA
B12: Bottom Funnel | C12: CAC (Zé Delivery) | D12: BF Squad | E12: 20.08 | F12: =Brahma!R11 -> 26.585643 | G12: =Budweiser!R11 -> 27.758836 | H12: =Corona!R11 -> 36.067415 | I12: =Spaten!R11 -> 25.691831 | J12: NA | K12: NA | L12: =BEER!R11 -> 29.56422 | M12: =Beats!R11 -> 0 | N12: NA | O12: NA | P12: NA | Q12: NA | R12: ='Flying Fish'!R11 -> NA | S12: ='Brutal Fruit'!R11 -> 452.76875 | T12: ='Zé Delivery'!R11 -> 24.193664 | U12: =PORTFOLIO!R11 -> 28.576829 | V12: NA | W12: NA | Y12: 34.37 | Z12: 49.16
C13: CPO (Zé Delivery) | E13: 1.75 | F13: =Brahma!R12 -> 5.5272893 | G13: =Budweiser!R12 -> 3.8268284 | H13: =Corona!R12 -> 3.8181057 | I13: =Spaten!R12 -> 5.887425 | J13: NA | K13: =Skol!R11 -> 0 | L13: =BEER!R12 -> 4.4687931 | M13: =Beats!R12 -> 0 | N13: NA | O13: NA | P13: NA | Q13: NA | R13: ='Flying Fish'!R12 -> NA | S13: ='Brutal Fruit'!R12 -> NA | T13: ='Zé Delivery'!R12 -> 3.1270988 | U13: =PORTFOLIO!R12 -> 3.9019209 | V13: NA | W13: NA | Y13: 3.12 | Z13: 9.13
B14: Production | C14: Briefing + 1st approval on time | D14: Modo | E14: 0.8 | F14: =Brahma!R13 -> NA | G14: =Budweiser!R13 -> 1 | H14: =Corona!R13 -> NA | I14: =Spaten!R13 -> 1 | J14: ='Stella Artois'!R11 -> 1 | K14: =Skol!R12 -> 1 | L14: =BEER!R13 -> 1 | M14: =Beats!R13 -> NA | N14: 1 | O14: =Tonica!R11 -> 0 | P14: =Fusion!R11 -> 0 | Q14: =Mikes!R11 -> 0 | R14: ='Flying Fish'!R13 -> NA | S14: ='Brutal Fruit'!R13 -> NA | T14: ='Zé Delivery'!R13 -> NA | U14: =PORTFOLIO!R13 -> 1 | V14: NA | W14: NA | Y14: 0.73 | Z14: 0.42
C15: % production vs media spend (# movies <20%) (TBD) | E15: 0.9 | F15: =Brahma!R14 -> NA | G15: =Budweiser!R14 -> 1 | H15: =Corona!R14 -> NA | I15: =Spaten!R14 -> NA | J15: ='Stella Artois'!R12 -> NA | K15: =Skol!R13 -> NA | L15: =BEER!R14 -> 0.13 | M15: =Beats!R14 -> NA | N15: 0.51 | O15: =Tonica!R12 -> 0 | P15: =Fusion!R12 -> 0 | Q15: =Mikes!R12 -> 0 | R15: ='Flying Fish'!R14 -> NA | S15: ='Brutal Fruit'!R14 -> NA | T15: ='Zé Delivery'!R14 -> NA | U15: =PORTFOLIO!R14 -> 0.16 | V15: =BEER!S14 -> 0.92 | W15: =PORTFOLIO!S14 -> 0.87 | Y15: 0.27 | Z15: NA
C16: Avoidable extra cost | E16: 0.05 | F16: =Brahma!R15 -> NA | G16: =Budweiser!R15 -> NA | H16: =Corona!R15 -> NA | I16: =Spaten!R15 -> NA | J16: ='Stella Artois'!R13 -> 0.0065 | K16: =Skol!R14 -> 0.0001 | L16: =BEER!R15 -> 0.0032 | M16: =Beats!R15 -> NA | N16: 0.04 | O16: =Tonica!R13 -> 0 | P16: =Fusion!R13 -> 0 | Q16: =Mikes!R13 -> 0 | R16: ='Flying Fish'!R15 -> NA | S16: ='Brutal Fruit'!R15 -> NA | T16: ='Zé Delivery'!R15 -> NA | U16: =PORTFOLIO!R15 -> 0.0125 | V16: NA | W16: NA | Y16: NA | Z16: NA

Sheet PORTFOLIO
X1: Portfolio
B2: ROI DASHBOARD - 2026
B3: PILAR | C3: KPI | D3: OWNER | E3: TARGET | F3: 46023 | G3: 46054 | H3: 46082 | I3: abr/26 | J3: mai/26 | K3: 46174 | L3: 46204 | M3: ago/26 | N3: set/26 | O3: out/26 | P3: 46327 | Q3: dez/26 | R3: YTD | S3: LE FY | T3: FY'25 | U3: FY'24 | V3: FY'23
B4: Audience first | C4: 1st Party Impressions | D4: Monks | E4: 22% - 32% | F4: =IFERROR(SUMIFS(Database!$O:$O, Database!$M:$M, "*Portfolio*", Database!$L:$L, MONTH(PORTFOLIO!F$3)) / SUMIFS(Database!$P:$P, Database!$M:$M, "*Portfolio*", Database!$L:$L, MONTH(PORTFOLIO!F$3)), "NA") -> 0.23846385 | G4: =IFERROR(SUMIFS(Database!$O:$O, Database!$M:$M, "*Portfolio*", Database!$L:$L, MONTH(PORTFOLIO!G$3)) / SUMIFS(Database!$P:$P, Database!$M:$M, "*Portfolio*", Database!$L:$L, MONTH(PORTFOLIO!G$3)), "") | H4: =IFERROR(SUMIFS(Database!$O:$O, Database!$M:$M, "*Portfolio*", Database!$L:$L, MONTH(PORTFOLIO!H$3)) / SUMIFS(Database!$P:$P, Database!$M:$M, "*Portfolio*", Database!$L:$L, MONTH(PORTFOLIO!H$3)), "") | I4: =IFERROR(SUMIFS(Database!$O:$O, Database!$M:$M, "*Portfolio*", Database!$L:$L, MONTH(PORTFOLIO!I$3)) / SUMIFS(Database!$P:$P, Database!$M:$M, "*Portfolio*", Database!$L:$L, MONTH(PORTFOLIO!I$3)), "") | J4: =IFERROR(SUMIFS(Database!$O:$O, Database!$M:$M, "*Portfolio*", Database!$L:$L, MONTH(PORTFOLIO!J$3)) / SUMIFS(Database!$P:$P, Database!$M:$M, "*Portfolio*", Database!$L:$L, MONTH(PORTFOLIO!J$3)), "") | K4: =IFERROR(SUMIFS(Database!$O:$O, Database!$M:$M, "*Portfolio*", Database!$L:$L, MONTH(PORTFOLIO!K$3)) / SUMIFS(Database!$P:$P, Database!$M:$M, "*Portfolio*", Database!$L:$L, MONTH(PORTFOLIO!K$3)), "") | L4: =IFERROR(SUMIFS(Database!$O:$O, Database!$M:$M, "*Portfolio*", Database!$L:$L, MONTH(PORTFOLIO!L$3)) / SUMIFS(Database!$P:$P, Database!$M:$M, "*Portfolio*", Database!$L:$L, MONTH(PORTFOLIO!L$3)), "") | M4: =IFERROR(SUMIFS(Database!$O:$O, Database!$M:$M, "*Portfolio*", Database!$L:$L, MONTH(PORTFOLIO!M$3)) / SUMIFS(Database!$P:$P, Database!$M:$M, "*Portfolio*", Database!$L:$L, MONTH(PORTFOLIO!M$3)), "") | N4: =IFERROR(SUMIFS(Database!$O:$O, Database!$M:$M, "*Portfolio*", Database!$L:$L, MONTH(PORTFOLIO!N$3)) / SUMIFS(Database!$P:$P, Database!$M:$M, "*Portfolio*", Database!$L:$L, MONTH(PORTFOLIO!N$3)), "") | ... Q4: =IFERROR(SUMIFS(Database!$O:$O, Database!$M:$M, "*Portfolio*", Database!$L:$L, MONTH(PORTFOLIO!Q$3)) / SUMIFS(Database!$P:$P, Database!$M:$M, "*Portfolio*", Database!$L:$L, MONTH(PORTFOLIO!Q$3)), "") | R4: =IFERROR(SUMIFS(Database!$O:$O, Database!$M:$M, "*Portfolio*") / SUMIFS(Database!$P:$P, Database!$M:$M, "*Portfolio*"), "") -> 0.23846385 | T4: 0.25 | U4: 0.28 | V4: 0.32
B5: Digital Assept Optimization | C5: Campaigns > 12 weeks | D5: Monks | E5: 0.8 | F5: =SUMIFS(Database!$U:$U,Database!$S:$S,$X$1,Database!$R:$R,MONTH(F$3)) -> 1 | G5: =IF(SUMIFS(Database!$U:$U,Database!$S:$S,$X$1,Database!$R:$R,MONTH(G$3))=0, "", SUMIFS(Database!$U:$U,Database!$S:$S,$X$1,Database!$R:$R,MONTH(G$3))) | H5: =IF(SUMIFS(Database!$U:$U,Database!$S:$S,$X$1,Database!$R:$R,MONTH(H$3))=0, "", SUMIFS(Database!$U:$U,Database!$S:$S,$X$1,Database!$R:$R,MONTH(H$3))) | I5: =IF(SUMIFS(Database!$U:$U,Database!$S:$S,$X$1,Database!$R:$R,MONTH(I$3))=0, "", SUMIFS(Database!$U:$U,Database!$S:$S,$X$1,Database!$R:$R,MONTH(I$3))) | J5: =IF(SUMIFS(Database!$U:$U,Database!$S:$S,$X$1,Database!$R:$R,MONTH(J$3))=0, "", SUMIFS(Database!$U:$U,Database!$S:$S,$X$1,Database!$R:$R,MONTH(J$3))) | K5: =IF(SUMIFS(Database!$U:$U,Database!$S:$S,$X$1,Database!$R:$R,MONTH(K$3))=0, "", SUMIFS(Database!$U:$U,Database!$S:$S,$X$1,Database!$R:$R,MONTH(K$3))) | L5: =IF(SUMIFS(Database!$U:$U,Database!$S:$S,$X$1,Database!$R:$R,MONTH(L$3))=0, "", SUMIFS(Database!$U:$U,Database!$S:$S,$X$1,Database!$R:$R,MONTH(L$3))) | M5: =IF(SUMIFS(Database!$U:$U,Database!$S:$S,$X$1,Database!$R:$R,MONTH(M$3))=0, "", SUMIFS(Database!$U:$U,Database!$S:$S,$X$1,Database!$R:$R,MONTH(M$3))) | N5: =IF(SUMIFS(Database!$U:$U,Database!$S:$S,$X$1,Database!$R:$R,MONTH(N$3))=0, "", SUMIFS(Database!$U:$U,Database!$S:$S,$X$1,Database!$R:$R,MONTH(N$3))) | ... Q5: =IF(SUMIFS(Database!$U:$U,Database!$S:$S,$X$1,Database!$R:$R,MONTH(Q$3))=0, "", SUMIFS(Database!$U:$U,Database!$S:$S,$X$1,Database!$R:$R,MONTH(Q$3))) | R5: =SUMIF(Database!$S:$S,$X$1,Database!$U:$U) -> 1 | S5: 1 | T5: 0.8 | U5: 0.56 | V5: N/A
C6: % of videos less than 10s | E6: 0.8 | F6: =IFERROR(SUMIFS(Database!$H:$H, Database!$C:$C, "*Portfolio*", Database!$D:$D, MONTH(PORTFOLIO!F$3)) / SUMIFS(Database!$G:$G, Database!$C:$C, "*Portfolio*", Database!$D:$D, MONTH(PORTFOLIO!F$3)), "NA") -> 0.90260754 | G6: =IFERROR(SUMIFS(Database!$H:$H, Database!$C:$C, "*Portfolio*", Database!$D:$D, MONTH(PORTFOLIO!G$3)) / SUMIFS(Database!$G:$G, Database!$C:$C, "*Portfolio*", Database!$D:$D, MONTH(PORTFOLIO!G$3)), "") | H6: =IFERROR(SUMIFS(Database!$H:$H, Database!$C:$C, "*Portfolio*", Database!$D:$D, MONTH(PORTFOLIO!H$3)) / SUMIFS(Database!$G:$G, Database!$C:$C, "*Portfolio*", Database!$D:$D, MONTH(PORTFOLIO!H$3)), "") | I6: =IFERROR(SUMIFS(Database!$H:$H, Database!$C:$C, "*Portfolio*", Database!$D:$D, MONTH(PORTFOLIO!I$3)) / SUMIFS(Database!$G:$G, Database!$C:$C, "*Portfolio*", Database!$D:$D, MONTH(PORTFOLIO!I$3)), "") | J6: =IFERROR(SUMIFS(Database!$H:$H, Database!$C:$C, "*Portfolio*", Database!$D:$D, MONTH(PORTFOLIO!J$3)) / SUMIFS(Database!$G:$G, Database!$C:$C, "*Portfolio*", Database!$D:$D, MONTH(PORTFOLIO!J$3)), "") | K6: =IFERROR(SUMIFS(Database!$H:$H, Database!$C:$C, "*Portfolio*", Database!$D:$D, MONTH(PORTFOLIO!K$3)) / SUMIFS(Database!$G:$G, Database!$C:$C, "*Portfolio*", Database!$D:$D, MONTH(PORTFOLIO!K$3)), "") | L6: =IFERROR(SUMIFS(Database!$H:$H, Database!$C:$C, "*Portfolio*", Database!$D:$D, MONTH(PORTFOLIO!L$3)) / SUMIFS(Database!$G:$G, Database!$C:$C, "*Portfolio*", Database!$D:$D, MONTH(PORTFOLIO!L$3)), "") | M6: =IFERROR(SUMIFS(Database!$H:$H, Database!$C:$C, "*Portfolio*", Database!$D:$D, MONTH(PORTFOLIO!M$3)) / SUMIFS(Database!$G:$G, Database!$C:$C, "*Portfolio*", Database!$D:$D, MONTH(PORTFOLIO!M$3)), "") | N6: =IFERROR(SUMIFS(Database!$H:$H, Database!$C:$C, "*Portfolio*", Database!$D:$D, MONTH(PORTFOLIO!N$3)) / SUMIFS(Database!$G:$G, Database!$C:$C, "*Portfolio*", Database!$D:$D, MONTH(PORTFOLIO!N$3)), "") | ... Q6: =IFERROR(SUMIFS(Database!$H:$H, Database!$C:$C, "*Portfolio*", Database!$D:$D, MONTH(PORTFOLIO!Q$3)) / SUMIFS(Database!$G:$G, Database!$C:$C, "*Portfolio*", Database!$D:$D, MONTH(PORTFOLIO!Q$3)), "") | R6: =IFERROR(SUMIFS(Database!$H:$H, Database!$C:$C, "*Portfolio*") / SUMIFS(Database!$G:$G, Database!$C:$C, "*Portfolio*"), "") -> 0.90260754 | T6: 0.62 | U6: 0.77 | V6: 0.7
C7: Weeks above minimum reach | D7: Meta | E7: 0.8 | T7: NA | U7: NA | V7: NA
C8: Weekly Frequency FB (>=2 e <=3) | E8: 0.8 | F8: 0.84 | R8: 0.84 | T8: 0.7 | U8: 0.55 | V8: 0.55
C9: YouTube Weekly Reach: >=30% + 4 Weeks | D9: Google | E9: 0.3 | F9: =IF(_xlfn.XLOOKUP("TOTAL PORTFOLIO", Database!$AG$4:$AG$19, Database!AI$4:AI$19)=0,"",_xlfn.XLOOKUP("TOTAL PORTFOLIO", Database!$AG$4:$AG$19, Database!AI$4:AI$19)) -> 0.262 | G9: =IF(_xlfn.XLOOKUP("TOTAL PORTFOLIO", Database!$AG$4:$AG$19, Database!AJ$4:AJ$19)=0,"",_xlfn.XLOOKUP("TOTAL PORTFOLIO", Database!$AG$4:$AG$19, Database!AJ$4:AJ$19)) | H9: =IF(_xlfn.XLOOKUP("TOTAL PORTFOLIO", Database!$AG$4:$AG$19, Database!AK$4:AK$19)=0,"",_xlfn.XLOOKUP("TOTAL PORTFOLIO", Database!$AG$4:$AG$19, Database!AK$4:AK$19)) | I9: =IF(_xlfn.XLOOKUP("TOTAL PORTFOLIO", Database!$AG$4:$AG$19, Database!AL$4:AL$19)=0,"",_xlfn.XLOOKUP("TOTAL PORTFOLIO", Database!$AG$4:$AG$19, Database!AL$4:AL$19)) | J9: =IF(_xlfn.XLOOKUP("TOTAL PORTFOLIO", Database!$AG$4:$AG$19, Database!AM$4:AM$19)=0,"",_xlfn.XLOOKUP("TOTAL PORTFOLIO", Database!$AG$4:$AG$19, Database!AM$4:AM$19)) | K9: =IF(_xlfn.XLOOKUP("TOTAL PORTFOLIO", Database!$AG$4:$AG$19, Database!AN$4:AN$19)=0,"",_xlfn.XLOOKUP("TOTAL PORTFOLIO", Database!$AG$4:$AG$19, Database!AN$4:AN$19)) | L9: =IF(_xlfn.XLOOKUP("TOTAL PORTFOLIO", Database!$AG$4:$AG$19, Database!AO$4:AO$19)=0,"",_xlfn.XLOOKUP("TOTAL PORTFOLIO", Database!$AG$4:$AG$19, Database!AO$4:AO$19)) | M9: =IF(_xlfn.XLOOKUP("TOTAL PORTFOLIO", Database!$AG$4:$AG$19, Database!AP$4:AP$19)=0,"",_xlfn.XLOOKUP("TOTAL PORTFOLIO", Database!$AG$4:$AG$19, Database!AP$4:AP$19)) | ... Q9: =IF(_xlfn.XLOOKUP("TOTAL PORTFOLIO", Database!$AG$4:$AG$19, Database!AT$4:AT$19)=0,"",_xlfn.XLOOKUP("TOTAL PORTFOLIO", Database!$AG$4:$AG$19, Database!AT$4:AT$19)) | R9: =IF(_xlfn.XLOOKUP("TOTAL PORTFOLIO", Database!$AG$4:$AG$19, Database!AH$4:AH$19)=0,"",_xlfn.XLOOKUP("TOTAL PORTFOLIO", Database!$AG$4:$AG$19, Database!AH$4:AH$19)) -> 0.262 | T9: 0.34 | U9: 0.32 | V9: 0.28
C10: AI Powered Video Reach Campaign + 2 Ad formats | E10: 0.45 | F10: =IF(_xlfn.XLOOKUP("TOTAL PORTFOLIO", Database!$AG$29:$AG$44,Database!AI$29:AI$44)=0,"",_xlfn.XLOOKUP("TOTAL PORTFOLIO", Database!$AG$29:$AG$44,Database!AI$29:AI$44)) -> 0.589 | G10: =IF(_xlfn.XLOOKUP("TOTAL PORTFOLIO", Database!$AG$29:$AG$44,Database!AJ$29:AJ$44)=0,"",_xlfn.XLOOKUP("TOTAL PORTFOLIO", Database!$AG$29:$AG$44,Database!AJ$29:AJ$44)) | H10: =IF(_xlfn.XLOOKUP("TOTAL PORTFOLIO", Database!$AG$29:$AG$44,Database!AK$29:AK$44)=0,"",_xlfn.XLOOKUP("TOTAL PORTFOLIO", Database!$AG$29:$AG$44,Database!AK$29:AK$44)) | I10: =IF(_xlfn.XLOOKUP("TOTAL PORTFOLIO", Database!$AG$29:$AG$44,Database!AL$29:AL$44)=0,"",_xlfn.XLOOKUP("TOTAL PORTFOLIO", Database!$AG$29:$AG$44,Database!AL$29:AL$44)) | J10: =IF(_xlfn.XLOOKUP("TOTAL PORTFOLIO", Database!$AG$29:$AG$44,Database!AM$29:AM$44)=0,"",_xlfn.XLOOKUP("TOTAL PORTFOLIO", Database!$AG$29:$AG$44,Database!AM$29:AM$44)) | K10: =IF(_xlfn.XLOOKUP("TOTAL PORTFOLIO", Database!$AG$29:$AG$44,Database!AN$29:AN$44)=0,"",_xlfn.XLOOKUP("TOTAL PORTFOLIO", Database!$AG$29:$AG$44,Database!AN$29:AN$44)) | L10: =IF(_xlfn.XLOOKUP("TOTAL PORTFOLIO", Database!$AG$29:$AG$44,Database!AO$29:AO$44)=0,"",_xlfn.XLOOKUP("TOTAL PORTFOLIO", Database!$AG$29:$AG$44,Database!AO$29:AO$44)) | M10: =IF(_xlfn.XLOOKUP("TOTAL PORTFOLIO", Database!$AG$29:$AG$44,Database!AP$29:AP$44)=0,"",_xlfn.XLOOKUP("TOTAL PORTFOLIO", Database!$AG$29:$AG$44,Database!AP$29:AP$44)) | ... Q10: =IF(_xlfn.XLOOKUP("TOTAL PORTFOLIO", Database!$AG$29:$AG$44,Database!AT$29:AT$44)=0,"",_xlfn.XLOOKUP("TOTAL PORTFOLIO", Database!$AG$29:$AG$44,Database!AT$29:AT$44)) | R10: =IF(_xlfn.XLOOKUP("TOTAL PORTFOLIO", Database!$AG$29:$AG$44,Database!AH$29:AH$44)=0,"",_xlfn.XLOOKUP("TOTAL PORTFOLIO", Database!$AG$29:$AG$44,Database!AH$29:AH$44)) -> 0.589 | T10: 61 | U10: NA | V10: NA
B11: Bottom Funnel Priorization | C11: CAC (Zé Delivery) | D11: BF Squad | E11: 20.08 | F11: =IFERROR(SUMIFS(Database!$AE:$AE, Database!$X:$X,"*"&$X$1&"*", Database!$W:$W, MONTH(F$3)) / SUMIFS(Database!$AD:$AD, Database!$X:$X,"*"&$X$1&"*", Database!$W:$W, MONTH(F$3)), "") -> 28.576829 | G11: =IFERROR(SUMIFS(Database!$AE:$AE, Database!$X:$X,"*"&$X$1&"*", Database!$W:$W, MONTH(G$3)) / SUMIFS(Database!$AD:$AD, Database!$X:$X,"*"&$X$1&"*", Database!$W:$W, MONTH(G$3)), "") | H11: =IFERROR(SUMIFS(Database!$AE:$AE, Database!$X:$X,"*"&$X$1&"*", Database!$W:$W, MONTH(H$3)) / SUMIFS(Database!$AD:$AD, Database!$X:$X,"*"&$X$1&"*", Database!$W:$W, MONTH(H$3)), "") | I11: =IFERROR(SUMIFS(Database!$AE:$AE, Database!$X:$X,"*"&$X$1&"*", Database!$W:$W, MONTH(I$3)) / SUMIFS(Database!$AD:$AD, Database!$X:$X,"*"&$X$1&"*", Database!$W:$W, MONTH(I$3)), "") | J11: =IFERROR(SUMIFS(Database!$AE:$AE, Database!$X:$X,"*"&$X$1&"*", Database!$W:$W, MONTH(J$3)) / SUMIFS(Database!$AD:$AD, Database!$X:$X,"*"&$X$1&"*", Database!$W:$W, MONTH(J$3)), "") | K11: =IFERROR(SUMIFS(Database!$AE:$AE, Database!$X:$X,"*"&$X$1&"*", Database!$W:$W, MONTH(K$3)) / SUMIFS(Database!$AD:$AD, Database!$X:$X,"*"&$X$1&"*", Database!$W:$W, MONTH(K$3)), "") | L11: =IFERROR(SUMIFS(Database!$AE:$AE, Database!$X:$X,"*"&$X$1&"*", Database!$W:$W, MONTH(L$3)) / SUMIFS(Database!$AD:$AD, Database!$X:$X,"*"&$X$1&"*", Database!$W:$W, MONTH(L$3)), "") | M11: =IFERROR(SUMIFS(Database!$AE:$AE, Database!$X:$X,"*"&$X$1&"*", Database!$W:$W, MONTH(M$3)) / SUMIFS(Database!$AD:$AD, Database!$X:$X,"*"&$X$1&"*", Database!$W:$W, MONTH(M$3)), "") | ... Q11: =IFERROR(SUMIFS(Database!$AE:$AE, Database!$X:$X,"*"&$X$1&"*", Database!$W:$W, MONTH(Q$3)) / SUMIFS(Database!$AD:$AD, Database!$X:$X,"*"&$X$1&"*", Database!$W:$W, MONTH(Q$3)), "") | R11: =IFERROR(SUMIFS(Database!$AE:$AE, Database!$X:$X,"*"&$X$1&"*") / SUMIFS(Database!$AD:$AD, Database!$X:$X,"*"&$X$1&"*"), "") -> 28.576829 | T11: 25.93 | U11: 34.37 | V11: 49.16
C12: CPO (Zé Delivery) | E12: 1.75 | F12: =IFERROR(SUMIFS(Database!$AC:$AC, Database!$X:$X,"*"&$X$1&"*", Database!$W:$W, MONTH(F$3)) / SUMIFS(Database!$AB:$AB, Database!$X:$X,"*"&$X$1&"*", Database!$W:$W, MONTH(F$3)), "") -> 3.9019209 | G12: =IFERROR(SUMIFS(Database!$AC:$AC, Database!$X:$X,"*"&$X$1&"*", Database!$W:$W, MONTH(G$3)) / SUMIFS(Database!$AB:$AB, Database!$X:$X,"*"&$X$1&"*", Database!$W:$W, MONTH(G$3)), "") | H12: =IFERROR(SUMIFS(Database!$AC:$AC, Database!$X:$X,"*"&$X$1&"*", Database!$W:$W, MONTH(H$3)) / SUMIFS(Database!$AB:$AB, Database!$X:$X,"*"&$X$1&"*", Database!$W:$W, MONTH(H$3)), "") | I12: =IFERROR(SUMIFS(Database!$AC:$AC, Database!$X:$X,"*"&$X$1&"*", Database!$W:$W, MONTH(I$3)) / SUMIFS(Database!$AB:$AB, Database!$X:$X,"*"&$X$1&"*", Database!$W:$W, MONTH(I$3)), "") | J12: =IFERROR(SUMIFS(Database!$AC:$AC, Database!$X:$X,"*"&$X$1&"*", Database!$W:$W, MONTH(J$3)) / SUMIFS(Database!$AB:$AB, Database!$X:$X,"*"&$X$1&"*", Database!$W:$W, MONTH(J$3)), "") | K12: =IFERROR(SUMIFS(Database!$AC:$AC, Database!$X:$X,"*"&$X$1&"*", Database!$W:$W, MONTH(K$3)) / SUMIFS(Database!$AB:$AB, Database!$X:$X,"*"&$X$1&"*", Database!$W:$W, MONTH(K$3)), "") | L12: =IFERROR(SUMIFS(Database!$AC:$AC, Database!$X:$X,"*"&$X$1&"*", Database!$W:$W, MONTH(L$3)) / SUMIFS(Database!$AB:$AB, Database!$X:$X,"*"&$X$1&"*", Database!$W:$W, MONTH(L$3)), "") | M12: =IFERROR(SUMIFS(Database!$AC:$AC, Database!$X:$X,"*"&$X$1&"*", Database!$W:$W, MONTH(M$3)) / SUMIFS(Database!$AB:$AB, Database!$X:$X,"*"&$X$1&"*", Database!$W:$W, MONTH(M$3)), "") | ... Q12: =IFERROR(SUMIFS(Database!$AC:$AC, Database!$X:$X,"*"&$X$1&"*", Database!$W:$W, MONTH(Q$3)) / SUMIFS(Database!$AB:$AB, Database!$X:$X,"*"&$X$1&"*", Database!$W:$W, MONTH(Q$3)), "") | R12: =IFERROR(SUMIFS(Database!$AC:$AC, Database!$X:$X,"*"&$X$1&"*") / SUMIFS(Database!$AB:$AB, Database!$X:$X,"*"&$X$1&"*"), "") -> 3.9019209 | T12: 1.94 | U12: 3.12 | V12: 4.93
B13: Production | C13: Briefing + 1st approval on time | D13: Modo | E13: 0.8 | F13: 1 | R13: 1 | T13: 0.92 | U13: 0.73 | V13: 0.42
C14: % production vs media spend (# movies <20%) | E14: 0.9 | F14: 0.16 | R14: 0.16 | S14: 0.87 | T14: 0.87 | U14: NA | V14: NA
C15: Avoidable extra cost | E15: 0.05 | F15: 0.0125 | R15: 0.0125 | T15: 0.05 | U15: NA | V15: NA

Sheet BEER
X1: Beer
B2: ROI DASHBOARD - 2026
B3: PILAR | C3: KPI | D3: OWNER | E3: TARGET | F3: 46023 | G3: 46054 | H3: 46082 | I3: abr/26 | J3: mai/26 | K3: 46174 | L3: 46204 | M3: ago/26 | N3: set/26 | O3: out/26 | P3: 46327 | Q3: dez/26 | R3: YTD | S3: LE FY | T3: FY'25 | U3: FY'24 | V3: FY'23
B4: Audience first | C4: 1st Party Impressions | D4: Monks | E4: 22% - 32% | F4: =IFERROR(SUMIFS(Database!$O:$O, Database!$M:$M, "*Beer*", Database!$L:$L, MONTH(F$3)) / SUMIFS(Database!$P:$P, Database!$M:$M, "*Beer*", Database!$L:$L, MONTH(F$3)), "") -> 0.21396285 | G4: =IFERROR(SUMIFS(Database!$O:$O, Database!$M:$M, "*Beer*", Database!$L:$L, MONTH(G$3)) / SUMIFS(Database!$P:$P, Database!$M:$M, "*Beer*", Database!$L:$L, MONTH(G$3)), "") | H4: =IFERROR(SUMIFS(Database!$O:$O, Database!$M:$M, "*Beer*", Database!$L:$L, MONTH(H$3)) / SUMIFS(Database!$P:$P, Database!$M:$M, "*Beer*", Database!$L:$L, MONTH(H$3)), "") | I4: =IFERROR(SUMIFS(Database!$O:$O, Database!$M:$M, "*Beer*", Database!$L:$L, MONTH(I$3)) / SUMIFS(Database!$P:$P, Database!$M:$M, "*Beer*", Database!$L:$L, MONTH(I$3)), "") | J4: =IFERROR(SUMIFS(Database!$O:$O, Database!$M:$M, "*Beer*", Database!$L:$L, MONTH(J$3)) / SUMIFS(Database!$P:$P, Database!$M:$M, "*Beer*", Database!$L:$L, MONTH(J$3)), "") | K4: =IFERROR(SUMIFS(Database!$O:$O, Database!$M:$M, "*Beer*", Database!$L:$L, MONTH(K$3)) / SUMIFS(Database!$P:$P, Database!$M:$M, "*Beer*", Database!$L:$L, MONTH(K$3)), "") | L4: =IFERROR(SUMIFS(Database!$O:$O, Database!$M:$M, "*Beer*", Database!$L:$L, MONTH(L$3)) / SUMIFS(Database!$P:$P, Database!$M:$M, "*Beer*", Database!$L:$L, MONTH(L$3)), "") | M4: =IFERROR(SUMIFS(Database!$O:$O, Database!$M:$M, "*Beer*", Database!$L:$L, MONTH(M$3)) / SUMIFS(Database!$P:$P, Database!$M:$M, "*Beer*", Database!$L:$L, MONTH(M$3)), "") | ... Q4: =IFERROR(SUMIFS(Database!$O:$O, Database!$M:$M, "*Beer*", Database!$L:$L, MONTH(Q$3)) / SUMIFS(Database!$P:$P, Database!$M:$M, "*Beer*", Database!$L:$L, MONTH(Q$3)), "") | R4: =IFERROR(SUMIFS(Database!$O:$O, Database!$M:$M, "*Beer*") / SUMIFS(Database!$P:$P, Database!$M:$M, "*Beer*"), "") -> 0.21396285 | S4: NA | T4: 0.27 | U4: 0.25 | V4: 0.25
B5: Digital Assept Optimization | C5: Campaigns > 12 weeks | D5: Monks | E5: 0.8 | F5: =SUMIFS(Database!$U:$U,Database!$S:$S,$X$1,Database!$R:$R,MONTH(F$3)) -> 1 | G5: =IF(SUMIFS(Database!$U:$U,Database!$S:$S,$X$1,Database!$R:$R,MONTH(G$3))=0, "", SUMIFS(Database!$U:$U,Database!$S:$S,$X$1,Database!$R:$R,MONTH(G$3))) | H5: =IF(SUMIFS(Database!$U:$U,Database!$S:$S,$X$1,Database!$R:$R,MONTH(H$3))=0, "", SUMIFS(Database!$U:$U,Database!$S:$S,$X$1,Database!$R:$R,MONTH(H$3))) | I5: =IF(SUMIFS(Database!$U:$U,Database!$S:$S,$X$1,Database!$R:$R,MONTH(I$3))=0, "", SUMIFS(Database!$U:$U,Database!$S:$S,$X$1,Database!$R:$R,MONTH(I$3))) | J5: =IF(SUMIFS(Database!$U:$U,Database!$S:$S,$X$1,Database!$R:$R,MONTH(J$3))=0, "", SUMIFS(Database!$U:$U,Database!$S:$S,$X$1,Database!$R:$R,MONTH(J$3))) | K5: =IF(SUMIFS(Database!$U:$U,Database!$S:$S,$X$1,Database!$R:$R,MONTH(K$3))=0, "", SUMIFS(Database!$U:$U,Database!$S:$S,$X$1,Database!$R:$R,MONTH(K$3))) | L5: =IF(SUMIFS(Database!$U:$U,Database!$S:$S,$X$1,Database!$R:$R,MONTH(L$3))=0, "", SUMIFS(Database!$U:$U,Database!$S:$S,$X$1,Database!$R:$R,MONTH(L$3))) | M5: =IF(SUMIFS(Database!$U:$U,Database!$S:$S,$X$1,Database!$R:$R,MONTH(M$3))=0, "", SUMIFS(Database!$U:$U,Database!$S:$S,$X$1,Database!$R:$R,MONTH(M$3))) | N5: =IF(SUMIFS(Database!$U:$U,Database!$S:$S,$X$1,Database!$R:$R,MONTH(N$3))=0, "", SUMIFS(Database!$U:$U,Database!$S:$S,$X$1,Database!$R:$R,MONTH(N$3))) | ... Q5: =IF(SUMIFS(Database!$U:$U,Database!$S:$S,$X$1,Database!$R:$R,MONTH(Q$3))=0, "", SUMIFS(Database!$U:$U,Database!$S:$S,$X$1,Database!$R:$R,MONTH(Q$3))) | R5: =SUMIF(Database!$S:$S,$X$1,Database!$U:$U) -> 1 | S5: 1 | T5: 1 | U5: 0.56 | V5: N/A
C6: % of videos less than 10s | E6: 0.8 | F6: =IFERROR(SUMIFS(Database!$H:$H, Database!$C:$C, "*Beer*", Database!$D:$D, MONTH(F$3)) / SUMIFS(Database!$G:$G, Database!$C:$C, "*Beer*", Database!$D:$D, MONTH(F$3)), "") -> 0.95684969 | G6: =IFERROR(SUMIFS(Database!$H:$H, Database!$C:$C, "*Beer*", Database!$D:$D, MONTH(G$3)) / SUMIFS(Database!$G:$G, Database!$C:$C, "*Beer*", Database!$D:$D, MONTH(G$3)), "") | H6: =IFERROR(SUMIFS(Database!$H:$H, Database!$C:$C, "*Beer*", Database!$D:$D, MONTH(H$3)) / SUMIFS(Database!$G:$G, Database!$C:$C, "*Beer*", Database!$D:$D, MONTH(H$3)), "") | I6: =IFERROR(SUMIFS(Database!$H:$H, Database!$C:$C, "*Beer*", Database!$D:$D, MONTH(I$3)) / SUMIFS(Database!$G:$G, Database!$C:$C, "*Beer*", Database!$D:$D, MONTH(I$3)), "") | J6: =IFERROR(SUMIFS(Database!$H:$H, Database!$C:$C, "*Beer*", Database!$D:$D, MONTH(J$3)) / SUMIFS(Database!$G:$G, Database!$C:$C, "*Beer*", Database!$D:$D, MONTH(J$3)), "") | K6: =IFERROR(SUMIFS(Database!$H:$H, Database!$C:$C, "*Beer*", Database!$D:$D, MONTH(K$3)) / SUMIFS(Database!$G:$G, Database!$C:$C, "*Beer*", Database!$D:$D, MONTH(K$3)), "") | L6: =IFERROR(SUMIFS(Database!$H:$H, Database!$C:$C, "*Beer*", Database!$D:$D, MONTH(L$3)) / SUMIFS(Database!$G:$G, Database!$C:$C, "*Beer*", Database!$D:$D, MONTH(L$3)), "") | M6: =IFERROR(SUMIFS(Database!$H:$H, Database!$C:$C, "*Beer*", Database!$D:$D, MONTH(M$3)) / SUMIFS(Database!$G:$G, Database!$C:$C, "*Beer*", Database!$D:$D, MONTH(M$3)), "") | ... Q6: =IFERROR(SUMIFS(Database!$H:$H, Database!$C:$C, "*Beer*", Database!$D:$D, MONTH(Q$3)) / SUMIFS(Database!$G:$G, Database!$C:$C, "*Beer*", Database!$D:$D, MONTH(Q$3)), "") | R6: =IFERROR(SUMIFS(Database!$H:$H, Database!$C:$C, "*Beer*") / SUMIFS(Database!$G:$G, Database!$C:$C, "*Beer*"), "") -> 0.95684969 | S6: NA | T6: 0.81 | U6: 0.74 | V6: 0.69
C7: Weeks above minimum reach | D7: Meta | E7: 0.8 | S7: NA | T7: NA | U7: NA | V7: NA
C8: Weekly Frequency FB (>=2 e <=3) | E8: 0.8 | F8: 0.86 | R8: 0.86 | S8: NA | T8: 0.71 | U8: 0.54 | V8: 0.56
C9: YouTube Weekly Reach: >=30% + 4 Weeks | D9: Google | E9: 0.3 | F9: =IF(_xlfn.XLOOKUP("TOTAL BEER", Database!$AG$4:$AG$19, Database!AI$4:AI$19)=0,"",_xlfn.XLOOKUP("TOTAL BEER", Database!$AG$4:$AG$19, Database!AI$4:AI$19)) -> 0.258 | G9: =IF(_xlfn.XLOOKUP("TOTAL PORTFOLIO", Database!$AG$4:$AG$19, Database!AJ$4:AJ$19)=0,"",_xlfn.XLOOKUP("TOTAL PORTFOLIO", Database!$AG$4:$AG$19, Database!AJ$4:AJ$19)) | H9: =IF(_xlfn.XLOOKUP("TOTAL PORTFOLIO", Database!$AG$4:$AG$19, Database!AK$4:AK$19)=0,"",_xlfn.XLOOKUP("TOTAL PORTFOLIO", Database!$AG$4:$AG$19, Database!AK$4:AK$19)) | I9: =IF(_xlfn.XLOOKUP("TOTAL PORTFOLIO", Database!$AG$4:$AG$19, Database!AL$4:AL$19)=0,"",_xlfn.XLOOKUP("TOTAL PORTFOLIO", Database!$AG$4:$AG$19, Database!AL$4:AL$19)) | J9: =IF(_xlfn.XLOOKUP("TOTAL PORTFOLIO", Database!$AG$4:$AG$19, Database!AM$4:AM$19)=0,"",_xlfn.XLOOKUP("TOTAL PORTFOLIO", Database!$AG$4:$AG$19, Database!AM$4:AM$19)) | K9: =IF(_xlfn.XLOOKUP("TOTAL PORTFOLIO", Database!$AG$4:$AG$19, Database!AN$4:AN$19)=0,"",_xlfn.XLOOKUP("TOTAL PORTFOLIO", Database!$AG$4:$AG$19, Database!AN$4:AN$19)) | L9: =IF(_xlfn.XLOOKUP("TOTAL PORTFOLIO", Database!$AG$4:$AG$19, Database!AO$4:AO$19)=0,"",_xlfn.XLOOKUP("TOTAL PORTFOLIO", Database!$AG$4:$AG$19, Database!AO$4:AO$19)) | M9: =IF(_xlfn.XLOOKUP("TOTAL PORTFOLIO", Database!$AG$4:$AG$19, Database!AP$4:AP$19)=0,"",_xlfn.XLOOKUP("TOTAL PORTFOLIO", Database!$AG$4:$AG$19, Database!AP$4:AP$19)) | N9: =IF(_xlfn.XLOOKUP("TOTAL PORTFOLIO", Database!$AG$4:$AG$19, Database!AQ$4:AQ$19)=0,"",_xlfn.XLOOKUP("TOTAL PORTFOLIO", Database!$AG$4:$AG$19, Database!AQ$4:AQ$19)) | ... Q9: =IF(_xlfn.XLOOKUP("TOTAL PORTFOLIO", Database!$AG$4:$AG$19, Database!AT$4:AT$19)=0,"",_xlfn.XLOOKUP("TOTAL PORTFOLIO", Database!$AG$4:$AG$19, Database!AT$4:AT$19)) | R9: =IF(_xlfn.XLOOKUP("TOTAL PORTFOLIO", Database!$AG$4:$AG$19, Database!AH$4:AH$19)=0,"",_xlfn.XLOOKUP("TOTAL PORTFOLIO", Database!$AG$4:$AG$19, Database!AH$4:AH$19)) -> 0.262 | S9: NA | T9: 0.34 | U9: 0.32 | V9: 0.27
C10: AI Powered Video Reach Campaign + 2 Ad formats | E10: 0.45 | F10: =IF(_xlfn.XLOOKUP("TOTAL BEER", Database!$AG$29:$AG$44,Database!AI$29:AI$44)=0,"",_xlfn.XLOOKUP("TOTAL BEER", Database!$AG$29:$AG$44,Database!AI$29:AI$44)) -> 0.582 | G10: =IF(_xlfn.XLOOKUP("TOTAL PORTFOLIO", Database!$AG$29:$AG$44,Database!AJ$29:AJ$44)=0,"",_xlfn.XLOOKUP("TOTAL PORTFOLIO", Database!$AG$29:$AG$44,Database!AJ$29:AJ$44)) | H10: =IF(_xlfn.XLOOKUP("TOTAL PORTFOLIO", Database!$AG$29:$AG$44,Database!AK$29:AK$44)=0,"",_xlfn.XLOOKUP("TOTAL PORTFOLIO", Database!$AG$29:$AG$44,Database!AK$29:AK$44)) | I10: =IF(_xlfn.XLOOKUP("TOTAL PORTFOLIO", Database!$AG$29:$AG$44,Database!AL$29:AL$44)=0,"",_xlfn.XLOOKUP("TOTAL PORTFOLIO", Database!$AG$29:$AG$44,Database!AL$29:AL$44)) | J10: =IF(_xlfn.XLOOKUP("TOTAL PORTFOLIO", Database!$AG$29:$AG$44,Database!AM$29:AM$44)=0,"",_xlfn.XLOOKUP("TOTAL PORTFOLIO", Database!$AG$29:$AG$44,Database!AM$29:AM$44)) | K10: =IF(_xlfn.XLOOKUP("TOTAL PORTFOLIO", Database!$AG$29:$AG$44,Database!AN$29:AN$44)=0,"",_xlfn.XLOOKUP("TOTAL PORTFOLIO", Database!$AG$29:$AG$44,Database!AN$29:AN$44)) | L10: =IF(_xlfn.XLOOKUP("TOTAL PORTFOLIO", Database!$AG$29:$AG$44,Database!AO$29:AO$44)=0,"",_xlfn.XLOOKUP("TOTAL PORTFOLIO", Database!$AG$29:$AG$44,Database!AO$29:AO$44)) | M10: =IF(_xlfn.XLOOKUP("TOTAL PORTFOLIO", Database!$AG$29:$AG$44,Database!AP$29:AP$44)=0,"",_xlfn.XLOOKUP("TOTAL PORTFOLIO", Database!$AG$29:$AG$44,Database!AP$29:AP$44)) | N10: =IF(_xlfn.XLOOKUP("TOTAL PORTFOLIO", Database!$AG$29:$AG$44,Database!AQ$29:AQ$44)=0,"",_xlfn.XLOOKUP("TOTAL PORTFOLIO", Database!$AG$29:$AG$44,Database!AQ$29:AQ$44)) | ... Q10: =IF(_xlfn.XLOOKUP("TOTAL PORTFOLIO", Database!$AG$29:$AG$44,Database!AT$29:AT$44)=0,"",_xlfn.XLOOKUP("TOTAL PORTFOLIO", Database!$AG$29:$AG$44,Database!AT$29:AT$44)) | R10: =IF(_xlfn.XLOOKUP("TOTAL PORTFOLIO", Database!$AG$29:$AG$44,Database!AH$29:AH$44)=0,"",_xlfn.XLOOKUP("TOTAL PORTFOLIO", Database!$AG$29:$AG$44,Database!AH$29:AH$44)) -> 0.589 | S10: NA | T10: 0.61 | U10: NA | V10: NA
B11: Bottom Funnel Priorization | C11: CAC (Zé Delivery) | D11: BF Squad | E11: 20.08 | F11: =IFERROR(SUMIFS(Database!$AE:$AE, Database!$X:$X,"*"&$X$1&"*", Database!$W:$W, MONTH(F$3)) / SUMIFS(Database!$AD:$AD, Database!$X:$X,"*"&$X$1&"*", Database!$W:$W, MONTH(F$3)), "") -> 29.56422 | G11: =IFERROR(SUMIFS(Database!$AE:$AE, Database!$X:$X,"*"&$X$1&"*", Database!$W:$W, MONTH(G$3)) / SUMIFS(Database!$AD:$AD, Database!$X:$X,"*"&$X$1&"*", Database!$W:$W, MONTH(G$3)), "") | H11: =IFERROR(SUMIFS(Database!$AE:$AE, Database!$X:$X,"*"&$X$1&"*", Database!$W:$W, MONTH(H$3)) / SUMIFS(Database!$AD:$AD, Database!$X:$X,"*"&$X$1&"*", Database!$W:$W, MONTH(H$3)), "") | I11: =IFERROR(SUMIFS(Database!$AE:$AE, Database!$X:$X,"*"&$X$1&"*", Database!$W:$W, MONTH(I$3)) / SUMIFS(Database!$AD:$AD, Database!$X:$X,"*"&$X$1&"*", Database!$W:$W, MONTH(I$3)), "") | J11: =IFERROR(SUMIFS(Database!$AE:$AE, Database!$X:$X,"*"&$X$1&"*", Database!$W:$W, MONTH(J$3)) / SUMIFS(Database!$AD:$AD, Database!$X:$X,"*"&$X$1&"*", Database!$W:$W, MONTH(J$3)), "") | K11: =IFERROR(SUMIFS(Database!$AE:$AE, Database!$X:$X,"*"&$X$1&"*", Database!$W:$W, MONTH(K$3)) / SUMIFS(Database!$AD:$AD, Database!$X:$X,"*"&$X$1&"*", Database!$W:$W, MONTH(K$3)), "") | L11: =IFERROR(SUMIFS(Database!$AE:$AE, Database!$X:$X,"*"&$X$1&"*", Database!$W:$W, MONTH(L$3)) / SUMIFS(Database!$AD:$AD, Database!$X:$X,"*"&$X$1&"*", Database!$W:$W, MONTH(L$3)), "") | M11: =IFERROR(SUMIFS(Database!$AE:$AE, Database!$X:$X,"*"&$X$1&"*", Database!$W:$W, MONTH(M$3)) / SUMIFS(Database!$AD:$AD, Database!$X:$X,"*"&$X$1&"*", Database!$W:$W, MONTH(M$3)), "") | ... Q11: =IFERROR(SUMIFS(Database!$AE:$AE, Database!$X:$X,"*"&$X$1&"*", Database!$W:$W, MONTH(Q$3)) / SUMIFS(Database!$AD:$AD, Database!$X:$X,"*"&$X$1&"*", Database!$W:$W, MONTH(Q$3)), "") | R11: =IFERROR(SUMIFS(Database!$AE:$AE, Database!$X:$X,"*"&$X$1&"*") / SUMIFS(Database!$AD:$AD, Database!$X:$X,"*"&$X$1&"*"), "") -> 29.56422 | S11: NA | T11: 25.89 | U11: 34.37 | V11: 49.16
C12: CPO (Zé Delivery) | E12: 1.75 | F12: =IFERROR(SUMIFS(Database!$AC:$AC, Database!$X:$X,"*"&$X$1&"*", Database!$W:$W, MONTH(F$3)) / SUMIFS(Database!$AB:$AB, Database!$X:$X,"*"&$X$1&"*", Database!$W:$W, MONTH(F$3)), "") -> 4.4687931 | G12: =IFERROR(SUMIFS(Database!$AC:$AC, Database!$X:$X,"*"&$X$1&"*", Database!$W:$W, MONTH(G$3)) / SUMIFS(Database!$AB:$AB, Database!$X:$X,"*"&$X$1&"*", Database!$W:$W, MONTH(G$3)), "") | H12: =IFERROR(SUMIFS(Database!$AC:$AC, Database!$X:$X,"*"&$X$1&"*", Database!$W:$W, MONTH(H$3)) / SUMIFS(Database!$AB:$AB, Database!$X:$X,"*"&$X$1&"*", Database!$W:$W, MONTH(H$3)), "") | I12: =IFERROR(SUMIFS(Database!$AC:$AC, Database!$X:$X,"*"&$X$1&"*", Database!$W:$W, MONTH(I$3)) / SUMIFS(Database!$AB:$AB, Database!$X:$X,"*"&$X$1&"*", Database!$W:$W, MONTH(I$3)), "") | J12: =IFERROR(SUMIFS(Database!$AC:$AC, Database!$X:$X,"*"&$X$1&"*", Database!$W:$W, MONTH(J$3)) / SUMIFS(Database!$AB:$AB, Database!$X:$X,"*"&$X$1&"*", Database!$W:$W, MONTH(J$3)), "") | K12: =IFERROR(SUMIFS(Database!$AC:$AC, Database!$X:$X,"*"&$X$1&"*", Database!$W:$W, MONTH(K$3)) / SUMIFS(Database!$AB:$AB, Database!$X:$X,"*"&$X$1&"*", Database!$W:$W, MONTH(K$3)), "") | L12: =IFERROR(SUMIFS(Database!$AC:$AC, Database!$X:$X,"*"&$X$1&"*", Database!$W:$W, MONTH(L$3)) / SUMIFS(Database!$AB:$AB, Database!$X:$X,"*"&$X$1&"*", Database!$W:$W, MONTH(L$3)), "") | M12: =IFERROR(SUMIFS(Database!$AC:$AC, Database!$X:$X,"*"&$X$1&"*", Database!$W:$W, MONTH(M$3)) / SUMIFS(Database!$AB:$AB, Database!$X:$X,"*"&$X$1&"*", Database!$W:$W, MONTH(M$3)), "") | ... Q12: =IFERROR(SUMIFS(Database!$AC:$AC, Database!$X:$X,"*"&$X$1&"*", Database!$W:$W, MONTH(Q$3)) / SUMIFS(Database!$AB:$AB, Database!$X:$X,"*"&$X$1&"*", Database!$W:$W, MONTH(Q$3)), "") | R12: =IFERROR(SUMIFS(Database!$AC:$AC, Database!$X:$X,"*"&$X$1&"*") / SUMIFS(Database!$AB:$AB, Database!$X:$X,"*"&$X$1&"*"), "") -> 4.4687931 | S12: NA | T12: 1.94 | U12: 3.12 | V12: 4.93
B13: Production | C13: Briefing + 1st approval on time | D13: Modo | E13: 0.8 | F13: 1 | R13: 1 | S13: NA | T13: 0.93 | U13: 0.77 | V13: 0.39
C14: % production vs media spend (# movies <20%) (TBD) | E14: 0.9 | F14: 0.13 | R14: 0.13 | S14: 0.92 | T14: 0.92 | U14: 0.27 | V14: NA
C15: Avoidable extra cost | E15: 0.05 | F15: 0.0032 | R15: 0.0032 | S15: NA | T15: 0.05 | U15: NA | V15: NA

Sheet Skol + Brahma
X1: Skol + Brahma
B2: ROI DASHBOARD - 2026
B3: PILAR | C3: KPI | D3: OWNER | E3: TARGET | F3: 46023 | G3: 46054 | H3: 46082 | I3: abr/26 | J3: mai/26 | K3: 46174 | L3: 46204 | M3: ago/26 | N3: set/26 | O3: out/26 | P3: 46327 | Q3: dez/26 | R3: YTD | S3: LE FY | T3: FY'25 | U3: FY'24 | V3: FY'23
B4: Digital Assept Optimization | C4: Campaigns > 12 weeks | D4: Monks | E4: 0.8 | F4: =SUMIFS(Database!$U:$U,Database!$S:$S,$X$1,Database!$R:$R,MONTH(F$3)) -> 1 | G4: =IF(SUMIFS(Database!$U:$U,Database!$S:$S,$X$1,Database!$R:$R,MONTH(G$3))=0, "", SUMIFS(Database!$U:$U,Database!$S:$S,$X$1,Database!$R:$R,MONTH(G$3))) | H4: =IF(SUMIFS(Database!$U:$U,Database!$S:$S,$X$1,Database!$R:$R,MONTH(H$3))=0, "", SUMIFS(Database!$U:$U,Database!$S:$S,$X$1,Database!$R:$R,MONTH(H$3))) | I4: =IF(SUMIFS(Database!$U:$U,Database!$S:$S,$X$1,Database!$R:$R,MONTH(I$3))=0, "", SUMIFS(Database!$U:$U,Database!$S:$S,$X$1,Database!$R:$R,MONTH(I$3))) | J4: =IF(SUMIFS(Database!$U:$U,Database!$S:$S,$X$1,Database!$R:$R,MONTH(J$3))=0, "", SUMIFS(Database!$U:$U,Database!$S:$S,$X$1,Database!$R:$R,MONTH(J$3))) | K4: =IF(SUMIFS(Database!$U:$U,Database!$S:$S,$X$1,Database!$R:$R,MONTH(K$3))=0, "", SUMIFS(Database!$U:$U,Database!$S:$S,$X$1,Database!$R:$R,MONTH(K$3))) | L4: =IF(SUMIFS(Database!$U:$U,Database!$S:$S,$X$1,Database!$R:$R,MONTH(L$3))=0, "", SUMIFS(Database!$U:$U,Database!$S:$S,$X$1,Database!$R:$R,MONTH(L$3))) | M4: =IF(SUMIFS(Database!$U:$U,Database!$S:$S,$X$1,Database!$R:$R,MONTH(M$3))=0, "", SUMIFS(Database!$U:$U,Database!$S:$S,$X$1,Database!$R:$R,MONTH(M$3))) | N4: =IF(SUMIFS(Database!$U:$U,Database!$S:$S,$X$1,Database!$R:$R,MONTH(N$3))=0, "", SUMIFS(Database!$U:$U,Database!$S:$S,$X$1,Database!$R:$R,MONTH(N$3))) | ... Q4: =IF(SUMIFS(Database!$U:$U,Database!$S:$S,$X$1,Database!$R:$R,MONTH(Q$3))=0, "", SUMIFS(Database!$U:$U,Database!$S:$S,$X$1,Database!$R:$R,MONTH(Q$3))) | R4: =SUMIF(Database!$S:$S,$X$1,Database!$U:$U) -> 1 | S4: 1 | T4: 1 | U4: 0.81 | V4: 0.99

Sheet Flying Fish
X1: Flying Fish
B2: ROI DASHBOARD - 2026
B3: PILAR | C3: KPI | D3: OWNER | E3: TARGET | F3: 46023 | G3: 46054 | H3: 46082 | I3: abr/26 | J3: mai/26 | K3: 46174 | L3: 46204 | M3: ago/26 | N3: set/26 | O3: out/26 | P3: 46327 | Q3: dez/26 | R3: YTD | S3: LE FY
B4: Audience first | C4: 1st Party Impressions | D4: Monks | E4: 22% - 32% | F4: =IFERROR(SUMIFS(Database!$O:$O, Database!$N:$N,"*" & $X$1 & "*", Database!$L:$L, MONTH(F$3)) / SUMIFS(Database!$P:$P, Database!$N:$N,"*" & $X$1 & "*", Database!$L:$L, MONTH(F$3)), "NA") -> NA | G4: =IFERROR(SUMIFS(Database!$O:$O, Database!$N:$N,"*" & $X$1 & "*", Database!$L:$L, MONTH(G$3)) / SUMIFS(Database!$P:$P, Database!$N:$N,"*" & $X$1 & "*", Database!$L:$L, MONTH(G$3)), "") | H4: =IFERROR(SUMIFS(Database!$O:$O, Database!$N:$N,"*" & $X$1 & "*", Database!$L:$L, MONTH(H$3)) / SUMIFS(Database!$P:$P, Database!$N:$N,"*" & $X$1 & "*", Database!$L:$L, MONTH(H$3)), "") | I4: =IFERROR(SUMIFS(Database!$O:$O, Database!$N:$N,"*" & $X$1 & "*", Database!$L:$L, MONTH(I$3)) / SUMIFS(Database!$P:$P, Database!$N:$N,"*" & $X$1 & "*", Database!$L:$L, MONTH(I$3)), "") | J4: =IFERROR(SUMIFS(Database!$O:$O, Database!$N:$N,"*" & $X$1 & "*", Database!$L:$L, MONTH(J$3)) / SUMIFS(Database!$P:$P, Database!$N:$N,"*" & $X$1 & "*", Database!$L:$L, MONTH(J$3)), "") | K4: =IFERROR(SUMIFS(Database!$O:$O, Database!$N:$N,"*" & $X$1 & "*", Database!$L:$L, MONTH(K$3)) / SUMIFS(Database!$P:$P, Database!$N:$N,"*" & $X$1 & "*", Database!$L:$L, MONTH(K$3)), "") | L4: =IFERROR(SUMIFS(Database!$O:$O, Database!$N:$N,"*" & $X$1 & "*", Database!$L:$L, MONTH(L$3)) / SUMIFS(Database!$P:$P, Database!$N:$N,"*" & $X$1 & "*", Database!$L:$L, MONTH(L$3)), "") | M4: =IFERROR(SUMIFS(Database!$O:$O, Database!$N:$N,"*" & $X$1 & "*", Database!$L:$L, MONTH(M$3)) / SUMIFS(Database!$P:$P, Database!$N:$N,"*" & $X$1 & "*", Database!$L:$L, MONTH(M$3)), "") | N4: =IFERROR(SUMIFS(Database!$O:$O, Database!$N:$N,"*" & $X$1 & "*", Database!$L:$L, MONTH(N$3)) / SUMIFS(Database!$P:$P, Database!$N:$N,"*" & $X$1 & "*", Database!$L:$L, MONTH(N$3)), "") | ... Q4: =IFERROR(SUMIFS(Database!$O:$O, Database!$N:$N,"*" & $X$1 & "*", Database!$L:$L, MONTH(Q$3)) / SUMIFS(Database!$P:$P, Database!$N:$N,"*" & $X$1 & "*", Database!$L:$L, MONTH(Q$3)), "") | R4: =IFERROR(SUMIFS(Database!$O:$O, Database!$N:$N,"*"& $X$1&"*") / SUMIFS(Database!$P:$P, Database!$N:$N,"*"& X1&"*"), "NA") -> NA
B5: Digital Assept Optimization | C5: Campaigns > 12 weeks | D5: Monks | E5: 0.8 | F5: =SUMIFS(Database!$U:$U,Database!$S:$S,$X$1,Database!$R:$R,MONTH(F$3)) -> 0 | G5: =IF(SUMIFS(Database!$U:$U,Database!$S:$S,$X$1,Database!$R:$R,MONTH(G$3))=0, "", SUMIFS(Database!$U:$U,Database!$S:$S,$X$1,Database!$R:$R,MONTH(G$3))) | H5: =IF(SUMIFS(Database!$U:$U,Database!$S:$S,$X$1,Database!$R:$R,MONTH(H$3))=0, "", SUMIFS(Database!$U:$U,Database!$S:$S,$X$1,Database!$R:$R,MONTH(H$3))) | I5: =IF(SUMIFS(Database!$U:$U,Database!$S:$S,$X$1,Database!$R:$R,MONTH(I$3))=0, "", SUMIFS(Database!$U:$U,Database!$S:$S,$X$1,Database!$R:$R,MONTH(I$3))) | J5: =IF(SUMIFS(Database!$U:$U,Database!$S:$S,$X$1,Database!$R:$R,MONTH(J$3))=0, "", SUMIFS(Database!$U:$U,Database!$S:$S,$X$1,Database!$R:$R,MONTH(J$3))) | K5: =IF(SUMIFS(Database!$U:$U,Database!$S:$S,$X$1,Database!$R:$R,MONTH(K$3))=0, "", SUMIFS(Database!$U:$U,Database!$S:$S,$X$1,Database!$R:$R,MONTH(K$3))) | L5: =IF(SUMIFS(Database!$U:$U,Database!$S:$S,$X$1,Database!$R:$R,MONTH(L$3))=0, "", SUMIFS(Database!$U:$U,Database!$S:$S,$X$1,Database!$R:$R,MONTH(L$3))) | M5: =IF(SUMIFS(Database!$U:$U,Database!$S:$S,$X$1,Database!$R:$R,MONTH(M$3))=0, "", SUMIFS(Database!$U:$U,Database!$S:$S,$X$1,Database!$R:$R,MONTH(M$3))) | N5: =IF(SUMIFS(Database!$U:$U,Database!$S:$S,$X$1,Database!$R:$R,MONTH(N$3))=0, "", SUMIFS(Database!$U:$U,Database!$S:$S,$X$1,Database!$R:$R,MONTH(N$3))) | ... Q5: =IF(SUMIFS(Database!$U:$U,Database!$S:$S,$X$1,Database!$R:$R,MONTH(Q$3))=0, "", SUMIFS(Database!$U:$U,Database!$S:$S,$X$1,Database!$R:$R,MONTH(Q$3))) | R5: =SUMIF(Database!$S:$S,$X$1,Database!$U:$U) -> 0
C6: % of videos less than 10s | E6: 0.8 | F6: =IFERROR(SUMIFS(Database!$H:$H, Database!$B:$B,"*" & $X$1 & "*", Database!$D:$D, MONTH(F$3)) / SUMIFS(Database!$G:$G, Database!$B:$B,"*" & $X$1 & "*", Database!$D:$D, MONTH(F$3)), "NA") -> NA | G6: =IFERROR(SUMIFS(Database!$H:$H, Database!$B:$B,"*" & $X$1 & "*", Database!$D:$D, MONTH(G$3)) / SUMIFS(Database!$G:$G, Database!$B:$B,"*" & $X$1 & "*", Database!$D:$D, MONTH(G$3)), "") | H6: =IFERROR(SUMIFS(Database!$H:$H, Database!$B:$B,"*" & $X$1 & "*", Database!$D:$D, MONTH(H$3)) / SUMIFS(Database!$G:$G, Database!$B:$B,"*" & $X$1 & "*", Database!$D:$D, MONTH(H$3)), "") | I6: =IFERROR(SUMIFS(Database!$H:$H, Database!$B:$B,"*" & $X$1 & "*", Database!$D:$D, MONTH(I$3)) / SUMIFS(Database!$G:$G, Database!$B:$B,"*" & $X$1 & "*", Database!$D:$D, MONTH(I$3)), "") | J6: =IFERROR(SUMIFS(Database!$H:$H, Database!$B:$B,"*" & $X$1 & "*", Database!$D:$D, MONTH(J$3)) / SUMIFS(Database!$G:$G, Database!$B:$B,"*" & $X$1 & "*", Database!$D:$D, MONTH(J$3)), "") | K6: =IFERROR(SUMIFS(Database!$H:$H, Database!$B:$B,"*" & $X$1 & "*", Database!$D:$D, MONTH(K$3)) / SUMIFS(Database!$G:$G, Database!$B:$B,"*" & $X$1 & "*", Database!$D:$D, MONTH(K$3)), "") | L6: =IFERROR(SUMIFS(Database!$H:$H, Database!$B:$B,"*" & $X$1 & "*", Database!$D:$D, MONTH(L$3)) / SUMIFS(Database!$G:$G, Database!$B:$B,"*" & $X$1 & "*", Database!$D:$D, MONTH(L$3)), "") | M6: =IFERROR(SUMIFS(Database!$H:$H, Database!$B:$B,"*" & $X$1 & "*", Database!$D:$D, MONTH(M$3)) / SUMIFS(Database!$G:$G, Database!$B:$B,"*" & $X$1 & "*", Database!$D:$D, MONTH(M$3)), "") | N6: =IFERROR(SUMIFS(Database!$H:$H, Database!$B:$B,"*" & $X$1 & "*", Database!$D:$D, MONTH(N$3)) / SUMIFS(Database!$G:$G, Database!$B:$B,"*" & $X$1 & "*", Database!$D:$D, MONTH(N$3)), "") | ... Q6: =IFERROR(SUMIFS(Database!$H:$H, Database!$B:$B,"*" & $X$1 & "*", Database!$D:$D, MONTH(Q$3)) / SUMIFS(Database!$G:$G, Database!$B:$B,"*" & $X$1 & "*", Database!$D:$D, MONTH(Q$3)), "") | R6: =IFERROR(SUMIFS(Database!$H:$H, Database!$B:$B,"*"& X1&"*") / SUMIFS(Database!$G:$G, Database!$B:$B,"*"& X1&"*"), "NA") -> NA
C7: Weeks above minimum reach | D7: Meta | E7: 0.8 | F7: 0.5 | R7: 0.5
C8: Weekly Frequency FB (>=2 e <=3) | E8: 0.8 | F8: 0.94 | R8: 0.94
C9: YouTube Weekly Reach: >=30% + 4 Weeks | D9: Google | E9: 0.3 | F9: =_xlfn.XLOOKUP($X$1, Database!$AG$4:$AG$19, Database!AI$4:AI$19) -> 0 | G9: =IF(_xlfn.XLOOKUP($X$1, Database!$AG$4:$AG$19, Database!AJ$4:AJ$19)=0,"",_xlfn.XLOOKUP($X$1, Database!$AG$4:$AG$19, Database!AJ$4:AJ$19)) | H9: =IF(_xlfn.XLOOKUP($X$1, Database!$AG$4:$AG$19, Database!AK$4:AK$19)=0,"",_xlfn.XLOOKUP($X$1, Database!$AG$4:$AG$19, Database!AK$4:AK$19)) | I9: =IF(_xlfn.XLOOKUP($X$1, Database!$AG$4:$AG$19, Database!AL$4:AL$19)=0,"",_xlfn.XLOOKUP($X$1, Database!$AG$4:$AG$19, Database!AL$4:AL$19)) | J9: =IF(_xlfn.XLOOKUP($X$1, Database!$AG$4:$AG$19, Database!AM$4:AM$19)=0,"",_xlfn.XLOOKUP($X$1, Database!$AG$4:$AG$19, Database!AM$4:AM$19)) | K9: =IF(_xlfn.XLOOKUP($X$1, Database!$AG$4:$AG$19, Database!AN$4:AN$19)=0,"",_xlfn.XLOOKUP($X$1, Database!$AG$4:$AG$19, Database!AN$4:AN$19)) | L9: =IF(_xlfn.XLOOKUP($X$1, Database!$AG$4:$AG$19, Database!AO$4:AO$19)=0,"",_xlfn.XLOOKUP($X$1, Database!$AG$4:$AG$19, Database!AO$4:AO$19)) | M9: =IF(_xlfn.XLOOKUP($X$1, Database!$AG$4:$AG$19, Database!AP$4:AP$19)=0,"",_xlfn.XLOOKUP($X$1, Database!$AG$4:$AG$19, Database!AP$4:AP$19)) | N9: =IF(_xlfn.XLOOKUP($X$1, Database!$AG$4:$AG$19, Database!AQ$4:AQ$19)=0,"",_xlfn.XLOOKUP($X$1, Database!$AG$4:$AG$19, Database!AQ$4:AQ$19)) | ... Q9: =IF(_xlfn.XLOOKUP($X$1, Database!$AG$4:$AG$19, Database!AT$4:AT$19)=0,"",_xlfn.XLOOKUP($X$1, Database!$AG$4:$AG$19, Database!AT$4:AT$19)) | R9: =IFERROR(_xlfn.XLOOKUP($X$1, Database!$AG$4:$AG$19, Database!AH$4:AH$19),"NA") -> NA
C10: AI Powered Video Reach Campaign + 2 Ad formats | E10: 0.45 | F10: =_xlfn.XLOOKUP($X$1, Database!$AG$29:$AG$44,Database!AI$29:AI$44) -> 0 | G10: =IF(_xlfn.XLOOKUP($X$1, Database!$AG$29:$AG$44,Database!AJ$29:AJ$44)=0,"",_xlfn.XLOOKUP($X$1, Database!$AG$29:$AG$44,Database!AJ$29:AJ$44)) | H10: =IF(_xlfn.XLOOKUP($X$1, Database!$AG$29:$AG$44,Database!AK$29:AK$44)=0,"",_xlfn.XLOOKUP($X$1, Database!$AG$29:$AG$44,Database!AK$29:AK$44)) | I10: =IF(_xlfn.XLOOKUP($X$1, Database!$AG$29:$AG$44,Database!AL$29:AL$44)=0,"",_xlfn.XLOOKUP($X$1, Database!$AG$29:$AG$44,Database!AL$29:AL$44)) | J10: =IF(_xlfn.XLOOKUP($X$1, Database!$AG$29:$AG$44,Database!AM$29:AM$44)=0,"",_xlfn.XLOOKUP($X$1, Database!$AG$29:$AG$44,Database!AM$29:AM$44)) | K10: =IF(_xlfn.XLOOKUP($X$1, Database!$AG$29:$AG$44,Database!AN$29:AN$44)=0,"",_xlfn.XLOOKUP($X$1, Database!$AG$29:$AG$44,Database!AN$29:AN$44)) | L10: =IF(_xlfn.XLOOKUP($X$1, Database!$AG$29:$AG$44,Database!AO$29:AO$44)=0,"",_xlfn.XLOOKUP($X$1, Database!$AG$29:$AG$44,Database!AO$29:AO$44)) | M10: =IF(_xlfn.XLOOKUP($X$1, Database!$AG$29:$AG$44,Database!AP$29:AP$44)=0,"",_xlfn.XLOOKUP($X$1, Database!$AG$29:$AG$44,Database!AP$29:AP$44)) | N10: =IF(_xlfn.XLOOKUP($X$1, Database!$AG$29:$AG$44,Database!AQ$29:AQ$44)=0,"",_xlfn.XLOOKUP($X$1, Database!$AG$29:$AG$44,Database!AQ$29:AQ$44)) | ... Q10: =IF(_xlfn.XLOOKUP($X$1, Database!$AG$29:$AG$44,Database!AT$29:AT$44)=0,"",_xlfn.XLOOKUP($X$1, Database!$AG$29:$AG$44,Database!AT$29:AT$44)) | R10: =IFERROR(_xlfn.XLOOKUP($X$1, Database!$AG$29:$AG$44,Database!AH$29:AH$44),"NA") -> NA
B11: Bottom Funnel Priorization | C11: CAC (Zé Delivery) | D11: BF Squad | E11: 20.08 | F11: =IF(SUMIFS(Database!$Z:$Z,Database!$Y:$Y,$X$1,Database!$W:$W,MONTH(F$3))=0, "NA", SUMIFS(Database!$Z:$Z,Database!$Y:$Y,$X$1,Database!$W:$W,MONTH(F$3))) -> NA | G11: =IF(SUMIFS(Database!$Z:$Z,Database!$Y:$Y,$X$1,Database!$W:$W,MONTH(G$3))=0, "", SUMIFS(Database!$Z:$Z,Database!$Y:$Y,$X$1,Database!$W:$W,MONTH(G$3))) | H11: =IF(SUMIFS(Database!$Z:$Z,Database!$Y:$Y,$X$1,Database!$W:$W,MONTH(H$3))=0, "", SUMIFS(Database!$Z:$Z,Database!$Y:$Y,$X$1,Database!$W:$W,MONTH(H$3))) | I11: =IF(SUMIFS(Database!$Z:$Z,Database!$Y:$Y,$X$1,Database!$W:$W,MONTH(I$3))=0, "", SUMIFS(Database!$Z:$Z,Database!$Y:$Y,$X$1,Database!$W:$W,MONTH(I$3))) | J11: =IF(SUMIFS(Database!$Z:$Z,Database!$Y:$Y,$X$1,Database!$W:$W,MONTH(J$3))=0, "", SUMIFS(Database!$Z:$Z,Database!$Y:$Y,$X$1,Database!$W:$W,MONTH(J$3))) | K11: =IF(SUMIFS(Database!$Z:$Z,Database!$Y:$Y,$X$1,Database!$W:$W,MONTH(K$3))=0, "", SUMIFS(Database!$Z:$Z,Database!$Y:$Y,$X$1,Database!$W:$W,MONTH(K$3))) | L11: =IF(SUMIFS(Database!$Z:$Z,Database!$Y:$Y,$X$1,Database!$W:$W,MONTH(L$3))=0, "", SUMIFS(Database!$Z:$Z,Database!$Y:$Y,$X$1,Database!$W:$W,MONTH(L$3))) | M11: =IF(SUMIFS(Database!$Z:$Z,Database!$Y:$Y,$X$1,Database!$W:$W,MONTH(M$3))=0, "", SUMIFS(Database!$Z:$Z,Database!$Y:$Y,$X$1,Database!$W:$W,MONTH(M$3))) | N11: =IF(SUMIFS(Database!$Z:$Z,Database!$Y:$Y,$X$1,Database!$W:$W,MONTH(N$3))=0, "", SUMIFS(Database!$Z:$Z,Database!$Y:$Y,$X$1,Database!$W:$W,MONTH(N$3))) | ... Q11: =IF(SUMIFS(Database!$Z:$Z,Database!$Y:$Y,$X$1,Database!$W:$W,MONTH(Q$3))=0, "", SUMIFS(Database!$Z:$Z,Database!$Y:$Y,$X$1,Database!$W:$W,MONTH(Q$3))) | R11: =IFERROR(SUMIFS(Database!$AE:$AE, Database!$Y:$Y, $X$1) / SUMIFS(Database!$AD:$AD, Database!$Y:$Y, $X$1), "NA") -> NA
C12: CPO (Zé Delivery) | E12: 1.75 | F12: =IF(SUMIFS(Database!$AA:$AA,Database!$Y:$Y,$X$1,Database!$W:$W,MONTH(F$3))=0, "NA", SUMIFS(Database!$AA:$AA,Database!$Y:$Y,$X$1,Database!$W:$W,MONTH(F$3))) -> NA | G12: =IF(SUMIFS(Database!$AA:$AA,Database!$Y:$Y,$X$1,Database!$W:$W,MONTH(G$3))=0, "", SUMIFS(Database!$AA:$AA,Database!$Y:$Y,$X$1,Database!$W:$W,MONTH(G$3))) | H12: =IF(SUMIFS(Database!$AA:$AA,Database!$Y:$Y,$X$1,Database!$W:$W,MONTH(H$3))=0, "", SUMIFS(Database!$AA:$AA,Database!$Y:$Y,$X$1,Database!$W:$W,MONTH(H$3))) | I12: =IF(SUMIFS(Database!$AA:$AA,Database!$Y:$Y,$X$1,Database!$W:$W,MONTH(I$3))=0, "", SUMIFS(Database!$AA:$AA,Database!$Y:$Y,$X$1,Database!$W:$W,MONTH(I$3))) | J12: =IF(SUMIFS(Database!$AA:$AA,Database!$Y:$Y,$X$1,Database!$W:$W,MONTH(J$3))=0, "", SUMIFS(Database!$AA:$AA,Database!$Y:$Y,$X$1,Database!$W:$W,MONTH(J$3))) | K12: =IF(SUMIFS(Database!$AA:$AA,Database!$Y:$Y,$X$1,Database!$W:$W,MONTH(K$3))=0, "", SUMIFS(Database!$AA:$AA,Database!$Y:$Y,$X$1,Database!$W:$W,MONTH(K$3))) | L12: =IF(SUMIFS(Database!$AA:$AA,Database!$Y:$Y,$X$1,Database!$W:$W,MONTH(L$3))=0, "", SUMIFS(Database!$AA:$AA,Database!$Y:$Y,$X$1,Database!$W:$W,MONTH(L$3))) | M12: =IF(SUMIFS(Database!$AA:$AA,Database!$Y:$Y,$X$1,Database!$W:$W,MONTH(M$3))=0, "", SUMIFS(Database!$AA:$AA,Database!$Y:$Y,$X$1,Database!$W:$W,MONTH(M$3))) | N12: =IF(SUMIFS(Database!$AA:$AA,Database!$Y:$Y,$X$1,Database!$W:$W,MONTH(N$3))=0, "", SUMIFS(Database!$AA:$AA,Database!$Y:$Y,$X$1,Database!$W:$W,MONTH(N$3))) | ... Q12: =IF(SUMIFS(Database!$AA:$AA,Database!$Y:$Y,$X$1,Database!$W:$W,MONTH(Q$3))=0, "", SUMIFS(Database!$AA:$AA,Database!$Y:$Y,$X$1,Database!$W:$W,MONTH(Q$3))) | R12: =IFERROR(SUMIFS(Database!$AC:$AC, Database!$Y:$Y, $X$1) / SUMIFS(Database!$AB:$AB, Database!$Y:$Y, $X$1), "NA") -> NA
B13: Production | C13: Briefing + 1st approval on time | D13: Modo | E13: 0.8 | F13: NA | R13: NA
C14: % production vs media spend (# movies <20%) (TBD) | E14: 0.9 | F14: NA | R14: NA
C15: Avoidable extra cost | E15: 0.05 | F15: NA | R15: NA

Sheet Brutal Fruit
X1: Brutal Fruit
B2: ROI DASHBOARD - 2026
B3: PILAR | C3: KPI | D3: OWNER | E3: TARGET | F3: 46023 | G3: 46054 | H3: 46082 | I3: abr/26 | J3: mai/26 | K3: 46174 | L3: 46204 | M3: ago/26 | N3: set/26 | O3: out/26 | P3: 46327 | Q3: dez/26 | R3: YTD | S3: LE FY
B4: Audience first | C4: 1st Party Impressions | D4: Monks | E4: 22% - 32% | F4: =IFERROR(SUMIFS(Database!$O:$O, Database!$N:$N,"*" & $X$1 & "*", Database!$L:$L, MONTH(F$3)) / SUMIFS(Database!$P:$P, Database!$N:$N,"*" & $X$1 & "*", Database!$L:$L, MONTH(F$3)), "NA") -> NA | G4: =IFERROR(SUMIFS(Database!$O:$O, Database!$N:$N,"*" & $X$1 & "*", Database!$L:$L, MONTH(G$3)) / SUMIFS(Database!$P:$P, Database!$N:$N,"*" & $X$1 & "*", Database!$L:$L, MONTH(G$3)), "") | H4: =IFERROR(SUMIFS(Database!$O:$O, Database!$N:$N,"*" & $X$1 & "*", Database!$L:$L, MONTH(H$3)) / SUMIFS(Database!$P:$P, Database!$N:$N,"*" & $X$1 & "*", Database!$L:$L, MONTH(H$3)), "") | I4: =IFERROR(SUMIFS(Database!$O:$O, Database!$N:$N,"*" & $X$1 & "*", Database!$L:$L, MONTH(I$3)) / SUMIFS(Database!$P:$P, Database!$N:$N,"*" & $X$1 & "*", Database!$L:$L, MONTH(I$3)), "") | J4: =IFERROR(SUMIFS(Database!$O:$O, Database!$N:$N,"*" & $X$1 & "*", Database!$L:$L, MONTH(J$3)) / SUMIFS(Database!$P:$P, Database!$N:$N,"*" & $X$1 & "*", Database!$L:$L, MONTH(J$3)), "") | K4: =IFERROR(SUMIFS(Database!$O:$O, Database!$N:$N,"*" & $X$1 & "*", Database!$L:$L, MONTH(K$3)) / SUMIFS(Database!$P:$P, Database!$N:$N,"*" & $X$1 & "*", Database!$L:$L, MONTH(K$3)), "") | L4: =IFERROR(SUMIFS(Database!$O:$O, Database!$N:$N,"*" & $X$1 & "*", Database!$L:$L, MONTH(L$3)) / SUMIFS(Database!$P:$P, Database!$N:$N,"*" & $X$1 & "*", Database!$L:$L, MONTH(L$3)), "") | M4: =IFERROR(SUMIFS(Database!$O:$O, Database!$N:$N,"*" & $X$1 & "*", Database!$L:$L, MONTH(M$3)) / SUMIFS(Database!$P:$P, Database!$N:$N,"*" & $X$1 & "*", Database!$L:$L, MONTH(M$3)), "") | N4: =IFERROR(SUMIFS(Database!$O:$O, Database!$N:$N,"*" & $X$1 & "*", Database!$L:$L, MONTH(N$3)) / SUMIFS(Database!$P:$P, Database!$N:$N,"*" & $X$1 & "*", Database!$L:$L, MONTH(N$3)), "") | ... Q4: =IFERROR(SUMIFS(Database!$O:$O, Database!$N:$N,"*" & $X$1 & "*", Database!$L:$L, MONTH(Q$3)) / SUMIFS(Database!$P:$P, Database!$N:$N,"*" & $X$1 & "*", Database!$L:$L, MONTH(Q$3)), "") | R4: =IFERROR(SUMIFS(Database!$O:$O, Database!$N:$N,"*"& $X$1&"*") / SUMIFS(Database!$P:$P, Database!$N:$N,"*"& X1&"*"), "NA") -> NA
B5: Digital Assept Optimization | C5: Campaigns > 12 weeks | D5: Monks | E5: 0.8 | F5: =SUMIFS(Database!$U:$U,Database!$S:$S,$X$1,Database!$R:$R,MONTH(F$3)) -> 0 | G5: =IF(SUMIFS(Database!$U:$U,Database!$S:$S,$X$1,Database!$R:$R,MONTH(G$3))=0, "", SUMIFS(Database!$U:$U,Database!$S:$S,$X$1,Database!$R:$R,MONTH(G$3))) | H5: =IF(SUMIFS(Database!$U:$U,Database!$S:$S,$X$1,Database!$R:$R,MONTH(H$3))=0, "", SUMIFS(Database!$U:$U,Database!$S:$S,$X$1,Database!$R:$R,MONTH(H$3))) | I5: =IF(SUMIFS(Database!$U:$U,Database!$S:$S,$X$1,Database!$R:$R,MONTH(I$3))=0, "", SUMIFS(Database!$U:$U,Database!$S:$S,$X$1,Database!$R:$R,MONTH(I$3))) | J5: =IF(SUMIFS(Database!$U:$U,Database!$S:$S,$X$1,Database!$R:$R,MONTH(J$3))=0, "", SUMIFS(Database!$U:$U,Database!$S:$S,$X$1,Database!$R:$R,MONTH(J$3))) | K5: =IF(SUMIFS(Database!$U:$U,Database!$S:$S,$X$1,Database!$R:$R,MONTH(K$3))=0, "", SUMIFS(Database!$U:$U,Database!$S:$S,$X$1,Database!$R:$R,MONTH(K$3))) | L5: =IF(SUMIFS(Database!$U:$U,Database!$S:$S,$X$1,Database!$R:$R,MONTH(L$3))=0, "", SUMIFS(Database!$U:$U,Database!$S:$S,$X$1,Database!$R:$R,MONTH(L$3))) | M5: =IF(SUMIFS(Database!$U:$U,Database!$S:$S,$X$1,Database!$R:$R,MONTH(M$3))=0, "", SUMIFS(Database!$U:$U,Database!$S:$S,$X$1,Database!$R:$R,MONTH(M$3))) | N5: =IF(SUMIFS(Database!$U:$U,Database!$S:$S,$X$1,Database!$R:$R,MONTH(N$3))=0, "", SUMIFS(Database!$U:$U,Database!$S:$S,$X$1,Database!$R:$R,MONTH(N$3))) | ... Q5: =IF(SUMIFS(Database!$U:$U,Database!$S:$S,$X$1,Database!$R:$R,MONTH(Q$3))=0, "", SUMIFS(Database!$U:$U,Database!$S:$S,$X$1,Database!$R:$R,MONTH(Q$3))) | R5: =SUMIF(Database!$S:$S,$X$1,Database!$U:$U) -> 0
C6: % of videos less than 10s | E6: 0.8 | F6: =IFERROR(SUMIFS(Database!$H:$H, Database!$B:$B,"*" & $X$1 & "*", Database!$D:$D, MONTH(F$3)) / SUMIFS(Database!$G:$G, Database!$B:$B,"*" & $X$1 & "*", Database!$D:$D, MONTH(F$3)), "") -> 0.40307293 | G6: =IFERROR(SUMIFS(Database!$H:$H, Database!$B:$B,"*" & $X$1 & "*", Database!$D:$D, MONTH(G$3)) / SUMIFS(Database!$G:$G, Database!$B:$B,"*" & $X$1 & "*", Database!$D:$D, MONTH(G$3)), "") | H6: =IFERROR(SUMIFS(Database!$H:$H, Database!$B:$B,"*" & $X$1 & "*", Database!$D:$D, MONTH(H$3)) / SUMIFS(Database!$G:$G, Database!$B:$B,"*" & $X$1 & "*", Database!$D:$D, MONTH(H$3)), "") | I6: =IFERROR(SUMIFS(Database!$H:$H, Database!$B:$B,"*" & $X$1 & "*", Database!$D:$D, MONTH(I$3)) / SUMIFS(Database!$G:$G, Database!$B:$B,"*" & $X$1 & "*", Database!$D:$D, MONTH(I$3)), "") | J6: =IFERROR(SUMIFS(Database!$H:$H, Database!$B:$B,"*" & $X$1 & "*", Database!$D:$D, MONTH(J$3)) / SUMIFS(Database!$G:$G, Database!$B:$B,"*" & $X$1 & "*", Database!$D:$D, MONTH(J$3)), "") | K6: =IFERROR(SUMIFS(Database!$H:$H, Database!$B:$B,"*" & $X$1 & "*", Database!$D:$D, MONTH(K$3)) / SUMIFS(Database!$G:$G, Database!$B:$B,"*" & $X$1 & "*", Database!$D:$D, MONTH(K$3)), "") | L6: =IFERROR(SUMIFS(Database!$H:$H, Database!$B:$B,"*" & $X$1 & "*", Database!$D:$D, MONTH(L$3)) / SUMIFS(Database!$G:$G, Database!$B:$B,"*" & $X$1 & "*", Database!$D:$D, MONTH(L$3)), "") | M6: =IFERROR(SUMIFS(Database!$H:$H, Database!$B:$B,"*" & $X$1 & "*", Database!$D:$D, MONTH(M$3)) / SUMIFS(Database!$G:$G, Database!$B:$B,"*" & $X$1 & "*", Database!$D:$D, MONTH(M$3)), "") | ... Q6: =IFERROR(SUMIFS(Database!$H:$H, Database!$B:$B,"*" & $X$1 & "*", Database!$D:$D, MONTH(Q$3)) / SUMIFS(Database!$G:$G, Database!$B:$B,"*" & $X$1 & "*", Database!$D:$D, MONTH(Q$3)), "") | R6: =IFERROR(SUMIFS(Database!$H:$H, Database!$B:$B,"*"& X1&"*") / SUMIFS(Database!$G:$G, Database!$B:$B,"*"& X1&"*"), "NA") -> 0.40307293
C7: Weeks above minimum reach | D7: Meta | E7: 0.8 | F7: 0.75 | R7: 0.75
C8: Weekly Frequency FB (>=2 e <=3) | E8: 0.8 | F8: 0 | R8: 0
